Workbook

Sheet Note
A1: Union Budget Analysis Dashboard for past 12 years | K1: PAGE 1 — Executive Overview | U1: Data Sources | Z1: ================================================================================
A2: Theme: | Z2: FORECAST METHODOLOGY: CPI & USD/INR for Feb & Mar 2026 (FY 2025-26)
K3: KPI cards: Total Revenue, Total Expenditure, Fiscal Deficit, Nominal GDP (selected year) | U3: Budget_Main & Growth_Calculation (Total Revenue, Expenditure, Fiscal Deficit, Nominal GDP) | Z3: ================================================================================
A4: Revenue vs Expenditure analysis | K4: Line chart: Revenue vs Expenditure vs GDP trend (2014-15 to 2025-26)
K5: Bar chart: Fiscal Deficit ₹ value by year | U5: Source | V5: Website | Z5: METHOD: OLS Linear Regression => y = alpha + beta * t
A6: Data: | K6: India map: State-wise revenue heatmap | U6: Union Budget Official Site | V6: indiabudget.gov.in
K7: Slicers: Financial Year, State/UT | U7: RBI Handbook of Statistics | V7: rbi.org.in | Z7: Where:
A8: Tax revenue (Direct & Indirect) | K8: Navigation bar on left/top with page icons across all pages | U8: Controller General of Accounts | V8: cga.nic.in | Z8: t = time index
K9: Consistent colour theme: Deep blue = Revenue, Orange/Red = Expenditure/Deficit, Green = GDP | U9: Ministry of Finance | V9: finmin.nic.in | Z9: Apr 2025 = 0
A10: Fiscal deficit | K10: One clean "story at a glance" for any stakeholder | Z10: May 2025 = 1
Z11: Jun 2025 = 2
A12: Capital vs Revenue expenditure | U12: Revenue_Detail (Income Tax, Corporate Tax, GST, Customs, Excise) | Z12: Jul 2025 = 3
Z13: Aug 2025 = 4
A14: Sector allocation (Defense, Education, Health) | K14: PAGE 2 — Revenue Details | U14: Source | V14: Website | Z14: Sep 2025 = 5
U15: CBDT | V15: incometaxindia.gov.in | Z15: Oct 2025 = 6
A16: State wise allocation | K16: Stacked bar: Tax Revenue vs Non-Tax Revenue vs Capital Receipts by year | U16: CBIC | V16: cbic.gov.in | Z16: Nov 2025 = 7
K17: Donut: Income Tax vs Corporate Tax vs GST vs Customs vs Excise (latest year) | U17: GST Council | V17: gstcouncil.gov.in | Z17: Dec 2025 = 8
A18: Inflation rate | K18: Line: Revenue Growth % YoY with annotations on big swings (2019-20 dip, 2021-22 surge) | U18: PIB Press Releases | V18: pib.gov.in | Z18: Jan 2026 = 9
K19: Table: Year-wise breakup of all revenue sub-heads | Z19: Feb 2026 = 10 [FORECAST]
A20: Rupee value | K20: Slicers: Financial Year, Revenue Category (Direct/Indirect/Non-Tax) | Z20: Mar 2026 = 11 [FORECAST]
K21: Tooltip page: Hover over any bar to see sub-head breakdown popup | U21: Expenditure_Detail (Defence, Education, Health, Agriculture, Infrastructure, Interest)
Z22: y = variable being forecast (CPI % or INR Rs/USD)
U23: Source | V23: Website
A24: Notes table6: | U24: Union Budget | V24: indiabudget.gov.in | Z24: Training data: 10 known months of FY 2025-26 only (Apr 2025 to Jan 2026)
A25: • CPI Mean = average of 12 monthly YoY CPI readings within the financial year (Apr–Mar). | K25: PAGE 3 — Expenditure Details | U25: Ministry of Education | V25: education.gov.in
A26: • INR Mean = average of 12 monthly USD/INR exchange rates within the financial year. | U26: Ministry of Health | V26: mohfw.gov.in | Z26: --------------------------------------------------------------------------------
A27: • YoY % Change = ((Current FY Mean − Previous FY Mean) / Previous FY Mean) × 100. | K27: Stacked bar: Revenue Expenditure vs Capital Expenditure by year | U27: Ministry of Defence | V27: mod.gov.in | Z27: OLS ESTIMATION FORMULAS
A28: • 2025-26: Feb & Mar 2026 forecasted via OLS regression fitted on the 10 known months of 2025-26 only (Apr 2025 – Jan 2026). | K28: Treemap: Sector-wise spending (Defence, Education, Health, Agriculture, Infrastructure, Interest Payments) | U28: DEA | V28: dea.gov.in | Z28: --------------------------------------------------------------------------------
A29: • Forecasted values — CPI: Feb=0.72%, Mar=0.52% | INR: Feb=₹86.96, Mar=₹87.31 | K29: Line: Capital Expenditure % of Total Expenditure trend
A30: • CPI regression: slope=-0.1992%/month, R²=0.313 | INR regression: slope=0.3413 ₹/month, R²=0.258 | K30: Bar: Top spending sectors per year | Z30: beta = SUM[(t - t_bar)(y - y_bar)] / SUM[(t - t_bar)^2]
A31: • Red = increase vs prior year | Green = decrease vs prior year | K31: Slicers: Year, Sector, Expenditure Type (Revenue/Capital) | U31: State_Data (State-wise Revenue & Expenditure for all 35 States/UTs)
A32: • Sources: CPI – MOSPI, GoI | USD/INR – RBI / Google Finance monthly averages. | K32: Tooltip page: Hover over treemap sector to see year-wise trend popup | Z32: alpha = y_bar - beta * t_bar
U33: Source | V33: Website
U34: RBI State Finances | V34: rbi.org.in | Z34: Where:
U35: CAG India | V35: cag.gov.in | Z35: t_bar = mean of t = (0+1+2+...+9) / 10 = 4.5
K36: PAGE 4 — Fiscal Deficit, Inflation & Rupee | U36: Finance Commission | V36: fincomindia.nic.in | Z36: y_bar = mean of the 10 known values of y
U37: NIPFP | V37: nipfp.org.in
K38: Dual-axis line: Fiscal Deficit % GDP (bar) + Rupee value vs USD (line) by year | Z38: Goodness of Fit:
K39: Quarterly line chart: Inflation rate by quarter across all years | Z39: R^2 = 1 - [ SUM(y - y_hat)^2 / SUM(y - y_bar)^2 ]
K40: Quarterly line chart: Rupee value by quarter | U40: Inflation_Rupee (Quarterly Inflation Rate & Rupee Value)
...

Sheet Budget_Main
A1: Financial Year | B1: Total Revenue(₹ crore) | C1: Tax Revenue(₹ crore) | D1: Non-Tax Revenue(₹ crore) | E1: Capital Receipts(₹ crore) | F1: Total Expenditure(₹ crore) | G1: Revenue Expenditure(₹ crore) | H1: Capital Expenditure(₹ crore) | I1: Fiscal Deficit(₹ crore) | J1: Nominal GDP(₹ crore)
A2: 2014-15 | B2: 1135000 | C2: 904000 | D2: 231000 | E2: 56000 | F2: 1663000 | G2: 1468000 | H2: 195000 | I2: 511000 | J2: 12468000
A3: 2015-16 | B3: 1245000 | C3: 944000 | D3: 301000 | E3: 42000 | F3: 1778000 | G3: 1539000 | H3: 239000 | I3: 535000 | J3: 13576000
A4: 2016-17 | B4: 1435000 | C4: 1103000 | D4: 332000 | E4: 59000 | F4: 1975000 | G4: 1691000 | H4: 284000 | I4: 536000 | J4: 15254000
A5: 2017-18 | B5: 1506000 | C5: 1203000 | D5: 303000 | E5: 100000 | F5: 2142000 | G5: 1879000 | H5: 300000 | I5: 591000 | J5: 17090000
A6: 2018-19 | B6: 1725000 | C6: 1317000 | D6: 408000 | E6: 87000 | F6: 2315000 | G6: 2007000 | H6: 337000 | I6: 649000 | J6: 18887000
A7: 2019-20 | B7: 1683000 | C7: 1356000 | D7: 327000 | E7: 65000 | F7: 2686000 | G7: 2349000 | H7: 336000 | I7: 934000 | J7: 20075000
A8: 2020-21 | B8: 1738000 | C8: 1424000 | D8: 314000 | E8: 24000 | F8: 3517000 | G8: 3011000 | H8: 426000 | I8: 1818000 | J8: 19746000
A9: 2021-22 | B9: 2205000 | C9: 1716000 | D9: 489000 | E9: 62000 | F9: 3794000 | G9: 3116000 | H9: 603000 | I9: 1587000 | J9: 23665000
A10: 2022-23 | B10: 2348000 | C10: 2027000 | D10: 321000 | E10: 56000 | F10: 4187000 | G10: 3449000 | H10: 728000 | I10: 1755000 | J10: 27241000
A11: 2023-24 | B11: 2756000 | C11: 2327000 | D11: 429000 | E11: 77000 | F11: 4490000 | G11: 3562000 | H11: 949000 | I11: 1654000 | J11: 30123000
A12: 2024-25 (RE) | B12: 3147000 | C12: 2557000 | D12: 590000 | E12: 88000 | F12: 4716000 | G12: 3723000 | H12: 1018000 | I12: 1613000 | J12: 33068000
A13: 2025-26 (BE) | B13: 3496000 | C13: 2837000 | D13: 659000 | E13: 59000 | F13: 5065000 | G13: 3944000 | H13: 1121000 | I13: 1569000 | J13: 35714000
C31: `

Sheet Growth_calculation
A1: Finacial year | B1: Revenue Growth | C1: Fiscal Deficit % GDP | D1: Captinal_expd of Total expd
A2: 2014-15 | B2: 0.085 | C2: 0.04 | D2: =Table7[[#This Row],[Capital Expenditure(₹ crore)]]/Table7[[#This Row],[Total Expenditure(₹ crore)]] -> 0.11725797
A3: 2015-16 | B3: =(Table7[[#This Row],[Total Revenue(₹ crore)]]-Budget_Main!B2)/Table7[[#This Row],[Total Revenue(₹ crore)]] -> 0.088353414 | C3: 0.035 | D3: =Table7[[#This Row],[Capital Expenditure(₹ crore)]]/Table7[[#This Row],[Total Expenditure(₹ crore)]] -> 0.1344207
A4: 2016-17 | B4: =(Table7[[#This Row],[Total Revenue(₹ crore)]]-Budget_Main!B3)/Table7[[#This Row],[Total Revenue(₹ crore)]] -> 0.13240418 | C4: 0.035 | D4: =Table7[[#This Row],[Capital Expenditure(₹ crore)]]/Table7[[#This Row],[Total Expenditure(₹ crore)]] -> 0.14379747
A5: 2017-18 | B5: =(Table7[[#This Row],[Total Revenue(₹ crore)]]-Budget_Main!B4)/Table7[[#This Row],[Total Revenue(₹ crore)]] -> 0.047144754 | C5: 0.035 | D5: =Table7[[#This Row],[Capital Expenditure(₹ crore)]]/Table7[[#This Row],[Total Expenditure(₹ crore)]] -> 0.14005602
A6: 2018-19 | B6: =(Table7[[#This Row],[Total Revenue(₹ crore)]]-Budget_Main!B5)/Table7[[#This Row],[Total Revenue(₹ crore)]] -> 0.12695652 | C6: 0.034 | D6: =Table7[[#This Row],[Capital Expenditure(₹ crore)]]/Table7[[#This Row],[Total Expenditure(₹ crore)]] -> 0.14557235
A7: 2019-20 | B7: =(Table7[[#This Row],[Total Revenue(₹ crore)]]-Budget_Main!B6)/Table7[[#This Row],[Total Revenue(₹ crore)]] -> -0.024955437 | C7: 0.046 | D7: =Table7[[#This Row],[Capital Expenditure(₹ crore)]]/Table7[[#This Row],[Total Expenditure(₹ crore)]] -> 0.12509308
A8: 2020-21 | B8: =(Table7[[#This Row],[Total Revenue(₹ crore)]]-Budget_Main!B7)/Table7[[#This Row],[Total Revenue(₹ crore)]] -> 0.03164557 | C8: 0.092 | D8: =Table7[[#This Row],[Capital Expenditure(₹ crore)]]/Table7[[#This Row],[Total Expenditure(₹ crore)]] -> 0.12112596
A9: 2021-22 | B9: =(Table7[[#This Row],[Total Revenue(₹ crore)]]-Budget_Main!B8)/Table7[[#This Row],[Total Revenue(₹ crore)]] -> 0.21179138 | C9: 0.067 | D9: =Table7[[#This Row],[Capital Expenditure(₹ crore)]]/Table7[[#This Row],[Total Expenditure(₹ crore)]] -> 0.15893516
A10: 2022-23 | B10: =(Table7[[#This Row],[Total Revenue(₹ crore)]]-Budget_Main!B9)/Table7[[#This Row],[Total Revenue(₹ crore)]] -> 0.060902896 | C10: 0.064 | D10: =Table7[[#This Row],[Capital Expenditure(₹ crore)]]/Table7[[#This Row],[Total Expenditure(₹ crore)]] -> 0.17387151
A11: 2023-24 | B11: =(Table7[[#This Row],[Total Revenue(₹ crore)]]-Budget_Main!B10)/Table7[[#This Row],[Total Revenue(₹ crore)]] -> 0.14804064 | C11: 0.056 | D11: =Table7[[#This Row],[Capital Expenditure(₹ crore)]]/Table7[[#This Row],[Total Expenditure(₹ crore)]] -> 0.21135857
A12: 2024-25 (RE) | B12: =(Table7[[#This Row],[Total Revenue(₹ crore)]]-Budget_Main!B11)/Table7[[#This Row],[Total Revenue(₹ crore)]] -> 0.12424531 | C12: 0.048 | D12: =Table7[[#This Row],[Capital Expenditure(₹ crore)]]/Table7[[#This Row],[Total Expenditure(₹ crore)]] -> 0.2158609
A13: 2025-26 (BE) | B13: =(Table7[[#This Row],[Total Revenue(₹ crore)]]-Budget_Main!B12)/Table7[[#This Row],[Total Revenue(₹ crore)]] -> 0.099828375 | C13: 0.044 | D13: =Table7[[#This Row],[Capital Expenditure(₹ crore)]]/Table7[[#This Row],[Total Expenditure(₹ crore)]] -> 0.2213228

Sheet Revenue_Detail
A1: Financial Year | B1: Category | C1: Sub-Head | D1: Value (₹ Crore)
A2: 2014-15 | B2: Direct Tax | C2: Income Tax | D2: 258326
A3: 2014-15 | B3: Direct Tax | C3: Corporate Tax | D3: 428925
A4: 2014-15 | B4: Indirect Tax | C4: GST | D4: N/A
A5: 2014-15 | B5: Indirect Tax | C5: Customs Duty | D5: 188016
A6: 2014-15 | B6: Indirect Tax | C6: Excise Duty | D6: 188128
A7: 2014-15 | B7: Non-Tax | C7: Dividends & Profits | D7: 89833
A8: 2014-15 | B8: Non-Tax | C8: Interest Receipts | D8: 23804
A9: 2015-16 | B9: Direct Tax | C9: Income Tax | D9: 291653
A10: 2015-16 | B10: Direct Tax | C10: Corporate Tax | D10: 452970
A11: 2015-16 | B11: Indirect Tax | C11: GST | D11: N/A
A12: 2015-16 | B12: Indirect Tax | C12: Customs Duty | D12: 209500
A13: 2015-16 | B13: Indirect Tax | C13: Excise Duty | D13: 283353
A14: 2015-16 | B14: Non-Tax | C14: Dividends & Profits | D14: 118271
A15: 2015-16 | B15: Non-Tax | C15: Interest Receipts | D15: 23142
A16: 2016-17 | B16: Direct Tax | C16: Income Tax | D16: 345776
A17: 2016-17 | B17: Direct Tax | C17: Corporate Tax | D17: 493924
A18: 2016-17 | B18: Indirect Tax | C18: GST | D18: N/A
A19: 2016-17 | B19: Indirect Tax | C19: Customs Duty | D19: 230000
A20: 2016-17 | B20: Indirect Tax | C20: Excise Duty | D20: 387369
A21: 2016-17 | B21: Non-Tax | C21: Dividends & Profits | D21: 123780
A22: 2016-17 | B22: Non-Tax | C22: Interest Receipts | D22: 29620
A23: 2017-18 | B23: Direct Tax | C23: Income Tax | D23: 430772
A24: 2017-18 | B24: Direct Tax | C24: Corporate Tax | D24: 571131
A25: 2017-18 | B25: Indirect Tax | C25: GST | D25: 444631
A26: 2017-18 | B26: Indirect Tax | C26: Customs Duty | D26: 135242
A27: 2017-18 | B27: Indirect Tax | C27: Excise Duty | D27: 276995
A28: 2017-18 | B28: Non-Tax | C28: Dividends & Profits | D28: 96905
A29: 2017-18 | B29: Non-Tax | C29: Interest Receipts | D29: 16554
A30: 2018-19 | B30: Direct Tax | C30: Income Tax | D30: 465277
... A85: 2025-26 (BE) | B85: Non-Tax | C85: Interest Receipts | D85: 50250

Sheet Expenditure_Detail
A1: Financial Year | B1: Sector | C1: Expenditure Type | D1: Amount (₹ Crore)
A2: 2014-15 | B2: Defence | C2: Revenue | D2: 212904
A3: 2014-15 | B3: Defence | C3: Capital | D3: 81965
A4: 2014-15 | B4: Education | C4: Revenue | D4: 69074
A5: 2014-15 | B5: Health | C5: Revenue | D5: 33278
A6: 2014-15 | B6: Agriculture | C6: Revenue | D6: 22652
A7: 2014-15 | B7: Infrastructure | C7: Capital | D7: 90180
A8: 2014-15 | B8: Interest Payments | C8: Revenue | D8: 402444
A9: 2015-16 | B9: Defence | C9: Revenue | D9: 167946
A10: 2015-16 | B10: Defence | C10: Capital | D10: 62451
A11: 2015-16 | B11: Education | C11: Revenue | D11: 72394
A12: 2015-16 | B12: Health | C12: Revenue | D12: 33152
A13: 2015-16 | B13: Agriculture | C13: Revenue | D13: 22978
... A85: 2025-26 (BE) | B85: Interest Payments | C85: Revenue | D85: 1276338

Sheet Inflation_rupee_month_wise
A1: Financial Year | B1: Month | C1: CPI Inflation YoY (%) | D1: USD/INR (Monthly Avg)
A2: 2014-15 | B2: April | C2: 8.48 | D2: 60.1
A3: 2014-15 | B3: May | C3: 8.33 | D3: 59.35
A4: 2014-15 | B4: June | C4: 6.77 | D4: 59.72
A5: 2014-15 | B5: July | C5: 7.39 | D5: 60.12
A6: 2014-15 | B6: August | C6: 7.03 | D6: 60.67
A7: 2014-15 | B7: September | C7: 5.63 | D7: 60.63
A8: 2014-15 | B8: October | C8: 4.62 | D8: 61.43
A9: 2014-15 | B9: November | C9: 3.27 | D9: 62.05
A10: 2014-15 | B10: December | C10: 4.28 | D10: 63.33
A11: 2014-15 | B11: January | C11: 5.19 | D11: 63.11
A12: 2014-15 | B12: February | C12: 5.37 | D12: 62.27
A13: 2014-15 | B13: March | C13: 5.25 | D13: 62.67
... A143: 2025-26 | B143: January | C143: 2.74 | D143: 90.79
A144: 2025-26 | B144: February
A145: 2025-26 | B145: March

Sheet inflation_rupee_quater_wise
A1: Financial Year | B1: Quarter | C1: CPI Inflation YoY (%) | D1: USD/INR (Quarterly Avg)
A2: 2014-15 | B2: Q1 | C2: 8.18 | D2: 61
A3: 2014-15 | B3: Q2 | C3: 6.71 | D3: 62
A4: 2014-15 | B4: Q3 | C4: 5.2 | D4: 62.5
A5: 2014-15 | B5: Q4 | C5: 7.46 | D5: 62.6
A6: 2015-16 | B6: Q1 | C6: 5.28 | D6: 63.8
A7: 2015-16 | B7: Q2 | C7: 4.88 | D7: 65
A8: 2015-16 | B8: Q3 | C8: 5.15 | D8: 65.8
A9: 2015-16 | B9: Q4 | C9: 5.35 | D9: 66.3
A10: 2016-17 | B10: Q1 | C10: 5.68 | D10: 66
A11: 2016-17 | B11: Q2 | C11: 5.05 | D11: 66.5
A12: 2016-17 | B12: Q3 | C12: 4.5 | D12: 67
A13: 2016-17 | B13: Q4 | C13: zz | D13: 64.8
A14: 2017-18 | B14: Q1 | C14: 4.51 | D14: 65.2
A15: 2017-18 | B15: Q2 | C15: 3.24 | D15: 66
A16: 2017-18 | B16: Q3 | C16: 3.58 | D16: 67
A17: 2017-18 | B17: Q4 | C17: 4.51 | D17: 65
A18: 2018-19 | B18: Q1 | C18: 4.86 | D18: 64.8
A19: 2018-19 | B19: Q2 | C19: 3.94 | D19: 68.4
A20: 2018-19 | B20: Q3 | C20: 3.42 | D20: 70
A21: 2018-19 | B21: Q4 | C21: 3.7 | D21: 69.1
A22: 2019-20 | B22: Q1 | C22: 3.05 | D22: 69.5
A23: 2019-20 | B23: Q2 | C23: 3.11 | D23: 70.5
A24: 2019-20 | B24: Q3 | C24: 4.62 | D24: 72.5
A25: 2019-20 | B25: Q4 | C25: 6.58 | D25: 73
... A49: 2025-26 | B49: Q4 | C49: 2.85 | D49: 90.5

Sheet Where the Rupee Comes From
A1: FY | B1: Category | C1: Amount (paise per ₹1)
A2: 2014–15 | B2: Income Tax | C2: 0.14
A3: 2014–15 | B3: Corporate Tax | C3: 0.21
A4: 2014–15 | B4: GST / Indirect Taxes | C4: 0.1
A5: 2014–15 | B5: Union Excise Duties | C5: 0.07
A6: 2014–15 | B6: Customs Duties | C6: 0.05
A7: 2014–15 | B7: Borrowings & Liabilities | C7: 0.25
A8: 2014–15 | B8: Non-Tax Revenue | C8: 0.09
A9: 2014–15 | B9: Other Receipts | C9: 0.09
A10: 2015–16 | B10: Income Tax | C10: 0.14
A11: 2015–16 | B11: Corporate Tax | C11: 0.2
A12: 2015–16 | B12: GST / Indirect Taxes | C12: 0.11
A13: 2015–16 | B13: Union Excise Duties | C13: 0.07
... A97: 2025–26 | B97: Other Receipts | C97: 0.02

Sheet Where the Rupee Goes
A1: FY | B1: Category | C1: Amount (paise per ₹1)
A2: 2014–15 | B2: Interest Payments | C2: 0.2
A3: 2014–15 | B3: States' Share of Taxes | C3: 0.18
A4: 2014–15 | B4: Central Sector Schemes | C4: 0.11
A5: 2014–15 | B5: Centrally Sponsored Schemes | C5: 0.09
A6: 2014–15 | B6: Defence | C6: 0.1
A7: 2014–15 | B7: Subsidies | C7: 0.12
A8: 2014–15 | B8: Pensions (Civil) | C8: 0.03
A9: 2014–15 | B9: Other Expenditure | C9: 0.17
A10: 2015–16 | B10: Interest Payments | C10: 0.21
A11: 2015–16 | B11: States' Share of Taxes | C11: 0.23
A12: 2015–16 | B12: Central Sector Schemes | C12: 0.12
A13: 2015–16 | B13: Centrally Sponsored Schemes | C13: 0.09
... A97: 2025–26 | B97: Other Expenditure | C97: 0.18

Sheet inflation_rupee_year_wise
A1: Financial Year | B1: CPI Mean (%) | C1: CPI YoY % Change | D1: INR Mean (₹ per $) | E1: INR YoY % Change
A2: 2014-15 | B2: 5.97 | D2: 61.29
A3: 2015-16 | B3: 4.88 | C3: -18.26 | D3: 65.5 | E3: 6.87
A4: 2016-17 | B4: 4.53 | C4: -7.17 | D4: 67.06 | E4: 2.38
A5: 2017-18 | B5: 3.6 | C5: -20.53 | D5: 64.51 | E5: -3.8
A6: 2018-19 | B6: 3.4 | C6: -5.56 | D6: 70.09 | E6: 8.65
A7: 2019-20 | B7: 4.8 | C7: 41.18 | D7: 70.92 | E7: 1.18
A8: 2020-21 | B8: 6.17 | C8: 28.54 | D8: 74.2 | E8: 4.62
A9: 2021-22 | B9: 5.52 | C9: -10.53 | D9: 74.7 | E9: 0.67
A10: 2022-23 | B10: 6.64 | C10: 20.29 | D10: 80.47 | E10: 7.72
A11: 2023-24 | B11: 5.37 | C11: -19.13 | D11: 82.79 | E11: 2.88
A12: 2024-25 | B12: 4.64 | C12: -13.59 | D12: 84.63 | E12: 2.22
A13: 2025-26 | B13: 1.62 | C13: -65.09 | D13: 85.43 | E13: 0.95

Sheet State_allocation
A1: Financial Year | B1: State / Union Territory | C1: Revenue Collected (₹ Crores) | D1: Expenditure (₹ Crores)
A2: 2014-15 | B2: Andhra Pradesh | C2: 121767 | D2: 130340
A3: 2014-15 | B3: Arunachal Pradesh | C3: 7496 | D3: 7759
A4: 2014-15 | B4: Assam | C4: 47274 | D4: 47288
A5: 2014-15 | B5: Bihar | C5: 90420 | D5: 88673
A6: 2014-15 | B6: Chhattisgarh | C6: 55861 | D6: 55125
A7: 2014-15 | B7: Goa | C7: 12502 | D7: 11661
A8: 2014-15 | B8: Gujarat | C8: 187101 | D8: 203781
A9: 2014-15 | B9: Haryana | C9: 80445 | D9: 89983
A10: 2014-15 | B10: Himachal Pradesh | C10: 21871 | D10: 20329
A11: 2014-15 | B11: Jharkhand | C11: 40033 | D11: 41861
A12: 2014-15 | B12: Karnataka | C12: 187606 | D12: 209509
A13: 2014-15 | B13: Kerala | C13: 106991 | D13: 102605
... A421: 2025-26 | B421: Puducherry | C421: 11288 | D421: 11345

Sheet Calendar
A1: Financial_Year | B1: Year_Start | C1: Year_End
A3: 2014-15 | B3: 2014 | C3: 2015
A4: 2015-16 | B4: 2015 | C4: 2016
A5: 2016-17 | B5: 2016 | C5: 2017
A6: 2017-18 | B6: 2017 | C6: 2018
A7: 2018-19 | B7: 2018 | C7: 2019
A8: 2019-20 | B8: 2019 | C8: 2020
A9: 2020-21 | B9: 2020 | C9: 2021
A10: 2021-22 | B10: 2021 | C10: 2022
A11: 2022-23 | B11: 2022 | C11: 2023
A12: 2023-24 | B12: 2023 | C12: 2024
A13: 2024-25 | B13: 2024 | C13: 2025
A14: 2025-26 | B14: 2025 | C14: 2026
